Workbook

Sheet 使用说明
A1: 产品规格识别测试集模板
A2: 用于构建人工标注基准集，并评估型号校验、规格准确率、证据质量、耗时和内存。
A4: 推荐工作流
A5: 步骤 | B5: 工作表 | C5: 操作 | D5: 完成标准
A6: 1 | B6: 采样计划 | C6: 按产品形态选择 20–30 份起步文档；优先覆盖不同厂商、数字版/扫描版和复杂表格。 | D6: 目标数与实际数差距接近 0
A7: 2 | B7: 案例清单 | C7: 每份 Datasheet 建立唯一案例 ID，登记型号、来源、文档类型和容易混淆的型号。 | D7: 一份文档一行
A8: 3 | B8: 标准答案 | C8: 逐字段填写人工确认的标准值、页码和原文证据；至少两人复核高风险字段。 | D8: 审核状态为 Approved
A9: 4 | B9: 型号评测 | C9: 每次算法运行填写预测型号和证据；判定列自动计算。 | D9: 无空白运行 ID/案例 ID
A10: 5 | B10: 规格评测 | C10: 每个标准答案字段复制一行；无预测则保持预测状态为空。额外预测使用空 GT_ID。 | D10: 判定列得到 TP/FP/FN/VALUE_ERROR
A11: 6 | B11: 运行记录 | C11: 记录算法版本、总耗时、解析/AI 耗时和峰值内存。 | D11: 每个 Run × Case 一行
A12: 核心指标定义
A13: 指标 | B13: 计算口径 | C13: 建议关注点 | D13: 说明
A14: 字段精确率 | B14: TP ÷ (TP + FP + VALUE_ERROR) | C14: 减少错误写入 | D14: 数值错误既不是正确预测，也消耗预测名额。
A15: 字段召回率 | B15: TP ÷ (TP + FN + VALUE_ERROR) | C15: 减少遗漏字段 | D15: 每个标准答案字段都必须出现在规格评测中。
A16: 字段 F1 | B16: 精确率与召回率的调和平均 | C16: 总体比较 | D16: 用于比较不同算法版本。
A17: 型号准确率 | B17: 正确型号判定 ÷ 型号评测案例数 | C17: 防止写错产品 | D17: False Accept 应作为最高风险错误。
A18: 证据正确率 | B18: Evidence Correct=Yes ÷ 已评价证据数 | C18: 可审计性 | D18: 页码与原文必须能支持该字段。
A19: 平均耗时/峰值内存 | B19: 按运行记录汇总 | C19: 部署可用性 | D19: 数字版与扫描版应分组比较。
A21: 填写规则与颜色
A22: 颜色 | B22: 含义 | C22: 规则
A23: 浅黄色 | B23: 人工输入 | C23: 由标注人员或系统运行结果填写。
A24: 浅灰色 | B24: 公式计算 | C24: 不要覆盖；扩展数据行时复制上一行公式。
A25: 浅绿色 | B25: 通过/正确 | C25: 自动条件格式。
A26: 浅红色 | B26: 错误/缺失 | C26: 需要检查标准答案、模型输出或字段定义。
A27: 标识符 | B27: Case_ID / GT_ID / Run_ID | C27: 建议格式：CASE-0001、GT-000001、RUN-YYYYMMDD-A。

Sheet 评测汇总
A1: 算法评测汇总
A2: 在 B3 输入 Run_ID；其余指标从型号评测、规格评测和运行记录自动计算。
A3: Selected Run_ID
A5: 准确率与召回率 | D5: 核心 KPI
A6: Metric | B6: Value | D6: KPI | E6: Value
A7: Model Cases | B7: =COUNTIF(型号评测!$A$6:$A$55,$B$3) -> 0 | D7: Field Precision | E7: =IFERROR($B$13/($B$13+$B$14+$B$16),0) -> 0
A8: Model Correct | B8: =COUNTIFS(型号评测!$A$6:$A$55,$B$3,型号评测!$I$6:$I$55,"Correct") -> 0 | D8: Field Recall | E8: =IFERROR($B$13/($B$13+$B$15+$B$16),0) -> 0
A9: Model Accuracy | B9: =IFERROR(B8/B7,0) -> 0 | D9: Field F1 | E9: =IFERROR(2*E7*E8/(E7+E8),0) -> 0
A10: False Accept | B10: =COUNTIFS(型号评测!$A$6:$A$55,$B$3,型号评测!$I$6:$I$55,"False Accept") -> 0 | D10: Evidence Accuracy | E10: =IFERROR(COUNTIFS(规格评测!$A$6:$A$105,$B$3,规格评测!$L$6:$L$105,"Yes")/COUNTIFS(规格评测!$A$6:$A$105,$B$3,规格评测!$L$6:$L$105,"<>"),0) -> 0
A11: False Reject | B11: =COUNTIFS(型号评测!$A$6:$A$55,$B$3,型号评测!$I$6:$I$55,"False Reject") -> 0 | D11: Average Total Seconds | E11: =IFERROR(AVERAGEIF(运行记录!$A$6:$A$55,$B$3,运行记录!$F$6:$F$55),0) -> 0
A12: Expected Spec Rows | B12: =COUNTIFS(规格评测!$A$6:$A$105,$B$3,规格评测!$C$6:$C$105,"<>") -> 0 | D12: Average Peak RAM MB | E12: =IFERROR(AVERAGEIF(运行记录!$A$6:$A$55,$B$3,运行记录!$I$6:$I$55),0) -> 0
A13: TP | B13: =COUNTIFS(规格评测!$A$6:$A$105,$B$3,规格评测!$M$6:$M$105,"TP") -> 0 | D13: Completed Cases | E13: =COUNTIFS(运行记录!$A$6:$A$55,$B$3,运行记录!$N$6:$N$55,"Completed") -> 0
A14: FP | B14: =COUNTIFS(规格评测!$A$6:$A$105,$B$3,规格评测!$M$6:$M$105,"FP") -> 0
A15: FN | B15: =COUNTIFS(规格评测!$A$6:$A$105,$B$3,规格评测!$M$6:$M$105,"FN") -> 0
A16: Value Errors | B16: =COUNTIFS(规格评测!$A$6:$A$105,$B$3,规格评测!$M$6:$M$105,"VALUE_ERROR") -> 0
A18: 判定口径
A19: TP | B19: 字段、状态和值均与标准答案一致。
A20: FP | B20: 系统输出了标准答案中不存在的字段。
A21: FN | B21: 标准答案存在字段，但系统没有输出预测状态。
A22: VALUE_ERROR | B22: 字段存在，但状态或标准化值不正确；同时影响精确率与召回率。
A23: False Accept | B23: 文档不属于目标型号，但系统接受；属于最高风险型号错误。
A24: 提示 | B24: 先填案例清单与标准答案，再录入运行结果。汇总为空时通常是 Run_ID 不一致。

Sheet 采样计划
A1: 按产品形态采样计划
A2: 默认每种产品形态 1 份，合计 30 份；Other/Unknown 可替换为高风险或复杂文档。
A4: Category | B4: Product Type Code | C4: Product Type | D4: Target | E4: Actual | F4: Gap | G4: Selection Notes
A5: Access Point | B5: ceiling | C5: Ceiling Mount | D5: 1 | E5: =COUNTIFS(案例清单!$D$6:$D$55,A5,案例清单!$E$6:$E$55,B5) -> 1 | F5: =D5-E5 -> 0
A6: Access Point | B6: wall | C6: Wall Mount | D6: 1 | E6: =COUNTIFS(案例清单!$D$6:$D$55,A6,案例清单!$E$6:$E$55,B6) -> 1 | F6: =D6-E6 -> 0
A7: Access Point | B7: wall_plate | C7: Wall Plate | D7: 1 | E7: =COUNTIFS(案例清单!$D$6:$D$55,A7,案例清单!$E$6:$E$55,B7) -> 0 | F7: =D7-E7 -> 1
A8: Access Point | B8: outdoor | C8: Outdoor | D8: 1 | E8: =COUNTIFS(案例清单!$D$6:$D$55,A8,案例清单!$E$6:$E$55,B8) -> 1 | F8: =D8-E8 -> 0
A9: Access Point | B9: desktop | C9: Desktop | D9: 1 | E9: =COUNTIFS(案例清单!$D$6:$D$55,A9,案例清单!$E$6:$E$55,B9) -> 0 | F9: =D9-E9 -> 1
A10: Access Point | B10: extender | C10: Extender | D10: 1 | E10: =COUNTIFS(案例清单!$D$6:$D$55,A10,案例清单!$E$6:$E$55,B10) -> 0 | F10: =D10-E10 -> 1
A11: Access Point | B11: other | C11: Other AP | D11: 1 | E11: =COUNTIFS(案例清单!$D$6:$D$55,A11,案例清单!$E$6:$E$55,B11) -> 0 | F11: =D11-E11 -> 1 | G11: 可替换为同类别复杂案例
A12: Accessories | B12: poe_injector | C12: PoE Injector | D12: 1 | E12: =COUNTIFS(案例清单!$D$6:$D$55,A12,案例清单!$E$6:$E$55,B12) -> 1 | F12: =D12-E12 -> 0
A13: Accessories | B13: power_supply | C13: Power Supply | D13: 1 | E13: =COUNTIFS(案例清单!$D$6:$D$55,A13,案例清单!$E$6:$E$55,B13) -> 0 | F13: =D13-E13 -> 1
A14: Accessories | B14: media_converter | C14: Media Converter | D14: 1 | E14: =COUNTIFS(案例清单!$D$6:$D$55,A14,案例清单!$E$6:$E$55,B14) -> 1 | F14: =D14-E14 -> 0
A15: Accessories | B15: optical_module | C15: Optical Module | D15: 1 | E15: =COUNTIFS(案例清单!$D$6:$D$55,A15,案例清单!$E$6:$E$55,B15) -> 1 | F15: =D15-E15 -> 0
A16: Accessories | B16: dac_cable | C16: DAC Cable | D16: 1 | E16: =COUNTIFS(案例清单!$D$6:$D$55,A16,案例清单!$E$6:$E$55,B16) -> 1 | F16: =D16-E16 -> 0
A17: Accessories | B17: mounting | C17: Mounting Accessory | D17: 1 | E17: =COUNTIFS(案例清单!$D$6:$D$55,A17,案例清单!$E$6:$E$55,B17) -> 0 | F17: =D17-E17 -> 1
A18: Accessories | B18: chassis | C18: Chassis | D18: 1 | E18: =COUNTIFS(案例清单!$D$6:$D$55,A18,案例清单!$E$6:$E$55,B18) -> 0 | F18: =D18-E18 -> 1
A19: Accessories | B19: antenna | C19: Antenna | D19: 1 | E19: =COUNTIFS(案例清单!$D$6:$D$55,A19,案例清单!$E$6:$E$55,B19) -> 0 | F19: =D19-E19 -> 1
A20: Accessories | B20: junction_box | C20: Junction Box | D20: 1 | E20: =COUNTIFS(案例清单!$D$6:$D$55,A20,案例清单!$E$6:$E$55,B20) -> 0 | F20: =D20-E20 -> 1
A21: Accessories | B21: other | C21: Other Accessory | D21: 1 | E21: =COUNTIFS(案例清单!$D$6:$D$55,A21,案例清单!$E$6:$E$55,B21) -> 0 | F21: =D21-E21 -> 1 | G21: 可替换为同类别复杂案例
A22: Gateway | B22: wired_router | C22: Wired Router | D22: 1 | E22: =COUNTIFS(案例清单!$D$6:$D$55,A22,案例清单!$E$6:$E$55,B22) -> 3 | F22: =D22-E22 -> -2
A23: Gateway | B23: wireless_router | C23: Wireless Router | D23: 1 | E23: =COUNTIFS(案例清单!$D$6:$D$55,A23,案例清单!$E$6:$E$55,B23) -> 1 | F23: =D23-E23 -> 0
A24: Gateway | B24: cellular_router | C24: Cellular Router | D24: 1 | E24: =COUNTIFS(案例清单!$D$6:$D$55,A24,案例清单!$E$6:$E$55,B24) -> 0 | F24: =D24-E24 -> 1
A25: Gateway | B25: outdoor_cellular_router | C25: Outdoor Cellular Router | D25: 1 | E25: =COUNTIFS(案例清单!$D$6:$D$55,A25,案例清单!$E$6:$E$55,B25) -> 0 | F25: =D25-E25 -> 1
A26: Gateway | B26: integrated_gateway | C26: Integrated Gateway | D26: 1 | E26: =COUNTIFS(案例清单!$D$6:$D$55,A26,案例清单!$E$6:$E$55,B26) -> 1 | F26: =D26-E26 -> 0
A27: Gateway | B27: other | C27: Other Router | D27: 1 | E27: =COUNTIFS(案例清单!$D$6:$D$55,A27,案例清单!$E$6:$E$55,B27) -> 0 | F27: =D27-E27 -> 1 | G27: 可替换为同类别复杂案例
A28: Managed Switch | B28: l2 | C28: Layer 2 | D28: 1 | E28: =COUNTIFS(案例清单!$D$6:$D$55,A28,案例清单!$E$6:$E$55,B28) -> 3 | F28: =D28-E28 -> -2
A29: Managed Switch | B29: l2_plus | C29: Layer 2+ | D29: 1 | E29: =COUNTIFS(案例清单!$D$6:$D$55,A29,案例清单!$E$6:$E$55,B29) -> 1 | F29: =D29-E29 -> 0
A30: Managed Switch | B30: l3 | C30: Layer 3 | D30: 1 | E30: =COUNTIFS(案例清单!$D$6:$D$55,A30,案例清单!$E$6:$E$55,B30) -> 4 | F30: =D30-E30 -> -3
A31: Managed Switch | B31: unknown | C31: Unknown Layer | D31: 1 | E31: =COUNTIFS(案例清单!$D$6:$D$55,A31,案例清单!$E$6:$E$55,B31) -> 0 | F31: =D31-E31 -> 1 | G31: 可替换为同类别复杂案例
A32: Unmanaged / Easy Smart Switch | B32: unmanaged | C32: Unmanaged | D32: 1 | E32: =COUNTIFS(案例清单!$D$6:$D$55,A32,案例清单!$E$6:$E$55,B32) -> 3 | F32: =D32-E32 -> -2
A33: Unmanaged / Easy Smart Switch | B33: easy_smart | C33: Easy Smart | D33: 1 | E33: =COUNTIFS(案例清单!$D$6:$D$55,A33,案例清单!$E$6:$E$55,B33) -> 0 | F33: =D33-E33 -> 1
A34: Unmanaged / Easy Smart Switch | B34: unknown | C34: Unknown Management Type | D34: 1 | E34: =COUNTIFS(案例清单!$D$6:$D$55,A34,案例清单!$E$6:$E$55,B34) -> 0 | F34: =D34-E34 -> 1 | G34: 可替换为同类别复杂案例
A36: 总计 | D36: =SUM(D5:D34) -> 30 | E36: =SUM(E5:E34) -> 23 | F36: =SUM(F5:F34) -> 7

Sheet 案例清单
A1: Datasheet 案例清单
A2: 每份文档一行；黄色列由标注人员填写。预留 50 行，可在表格末尾继续新增。
A5: Case_ID | B5: Brand | C5: Target_Model | D5: Category | E5: Product_Type_Code | F5: Region | G5: Language | H5: Document_URL_or_Path | I5: SHA256 | J5: Document_Kind | K5: Page_Count | L5: Layout_Complexity | M5: Has_Tables | N5: Has_Charts | O5: Similar_Models_Present | P5: Expected_Model_Match | Q5: Confusing_Model | R5: Annotation_Status | S5: Annotator | T5: Reviewer | U5: Notes
A6: CASE-0001 | B6: Reyee | C6: RG-RAP72 | D6: Access Point | E6: ceiling | F6: US | G6: English | H6: D:\APProductDB\media\datasheets\reyee\RGRAP72\dbb263c1d5a04bc491a3dc8b906a5608.pdf | I6: DB916B8172FA7A93CEBDC5596B3617453D3E8F73CC62AD581D99E8FEA66563CF | J6: Digital PDF | K6: 17 | L6: High | M6: Yes | N6: No | O6: No | P6: Yes | R6: In Review | S6: Codex (reference draft) | U6: 基于上传 PDF 逐页核验；正式来源：https://reyee.ruijie.com/en-global/resources/preview/rg-rap72-datasheet/。请由业务人员复核后改为 Approved。
A7: CASE-0002 | B7: DrayTek | C7: Vigor2927 | D7: Gateway | E7: wired_router | F7: UN | G7: English | H7: C:\Users\admin\Desktop\test\2927 datasheet-5G-260701.pdf | I7: 1BCD8F790FAC3FA702A7C40FA312EA447D768DC8C3A28524ABCF85D9B5B03E74 | J7: Digital PDF | K7: 2 | L7: Low | M7: Yes | N7: No | O7: Yes | P7: Yes | Q7: Vigor2927ax; Vigor2927L; Vigor2927L-5G; Vigor2927Vac; Vigor2927Lac | R7: In Review | S7: Codex (batch reference draft) | U7: 批量参考草稿；需由业务人员逐条复核后改为 Approved。 该 PDF 包含多个相近型号，标准答案仅针对 Target_Model。
A8: CASE-0003 | B8: DrayTek | C8: Vigor2962 | D8: Gateway | E8: wired_router | F8: UN | G8: English | H8: C:\Users\admin\Desktop\test\2962 datasheet-260701.pdf | I8: EEF0871ED56DED4A4BF55225217824FCDE53E2EE81BFB5C29E9B3E2E6232D337 | J8: Digital PDF | K8: 2 | L8: Low | M8: Yes | N8: No | O8: No | P8: Yes | R8: In Review | S8: Codex (batch reference draft) | U8: 批量参考草稿；需由业务人员逐条复核后改为 Approved。
A9: CASE-0004 | B9: NETGEAR | C9: GS305 | D9: Unmanaged / Easy Smart Switch | E9: unmanaged | F9: UN | G9: English | H9: C:\Users\admin\Desktop\test\300-Series_Gigabit_DS.pdf | I9: C50C2386463495FB01376925BD5DAC9A73FAC0649D51080E33FDF38ACDCBEBED | J9: Digital PDF | K9: 6 | L9: Medium | M9: Yes | N9: No | O9: Yes | P9: Yes | Q9: GS308; GS324; GS348 | R9: In Review | S9: Codex (batch reference draft) | U9: 批量参考草稿；需由业务人员逐条复核后改为 Approved。 该 PDF 包含多个相近型号，标准答案仅针对 Target_Model。
A10: CASE-0005 | B10: MikroTik | C10: CCR1009-7G-1C-1S+ | D10: Gateway | E10: wired_router | F10: UN | G10: English | H10: C:\Users\admin\Desktop\test\CCR1009-7G-1C-1S_210502.pdf | I10: C0A200D399A3B889CD36CA03BA117C6A398DA31417EBB80753EE423B92D6CB28 | J10: Digital PDF | K10: 2 | L10: Low | M10: Yes | N10: No | O10: No | P10: Yes | R10: In Review | S10: Codex (batch reference draft) | U10: 批量参考草稿；需由业务人员逐条复核后改为 Approved。
A11: CASE-0006 | B11: Cisco | C11: QSFP-100G-SR4-S | D11: Accessories | E11: optical_module | F11: UN | G11: English | H11: C:\Users\admin\Desktop\test\datasheet-c78-736282.pdf | I11: 2505CF51617A665B2F999AFB6FB1C21FBB7ED360A8799A2A5EA1534C42002A31 | J11: Digital PDF | K11: 21 | L11: High | M11: Yes | N11: No | O11: Yes | P11: Yes | Q11: Other Cisco QSFP-100G optical modules in the same datasheet | R11: In Review | S11: Codex (batch reference draft) | U11: 批量参考草稿；需由业务人员逐条复核后改为 Approved。 该 PDF 包含多个相近型号，标准答案仅针对 Target_Model。
A12: CASE-0007 | B12: Dahua | C12: DH-PFS3010-8ET-65 | D12: Unmanaged / Easy Smart Switch | E12: unmanaged | F12: UN | G12: English | H12: C:\Users\admin\Desktop\test\DH-PFS3010-8ET-65_datasheet.pdf | I12: 53F6FBF29DC3D423B0F49B98FBE588C92B830FEAAAFE5E16B8E925D3D02DFFA1 | J12: Digital PDF | K12: 2 | L12: Low | M12: Yes | N12: No | O12: No | P12: Yes | R12: In Review | S12: Codex (batch reference draft) | U12: 批量参考草稿；需由业务人员逐条复核后改为 Approved。
A13: CASE-0008 | B13: D-Link | C13: DMC-G01LC | D13: Accessories | E13: media_converter | F13: UN | G13: English | H13: C:\Users\admin\Desktop\test\DMC_G01LC_B1_Datasheet_EN_EU.pdf | I13: 6BB26400C645492E6A75DFF461D47118B384E18D6DC9C10A02F4CFD3D60655BD | J13: Digital PDF | K13: 2 | L13: Low | M13: Yes | N13: No | O13: No | P13: Yes | R13: In Review | S13: Codex (batch reference draft) | U13: 批量参考草稿；需由业务人员逐条复核后改为 Approved。
A14: CASE-0009 | B14: Hikvision | C14: DS-3E1505P-EI/M | D14: Managed Switch | E14: l2 | F14: UN | G14: English | H14: C:\Users\admin\Desktop\test\DS-3E1505P-EI_M_Datasheet_20231023.pdf | I14: C68E741544637E468C92C0C2896650EE97E877AACBDA54DDE398A7B36B6E7D4E | J14: Digital PDF | K14: 6 | L14: Medium | M14: Yes | N14: No | O14: No | P14: Yes | R14: In Review | S14: Codex (batch reference draft) | U14: 批量参考草稿；需由业务人员逐条复核后改为 Approved。
A15: CASE-0010 | B15: Hikvision | C15: DS-3WF02C-5AC/O | D15: Wireless Bridge | F15: US | G15: English | H15: C:\Users\admin\Desktop\test\DS-3WF02C-5AC_O_Datasheet_20260305.pdf | I15: C3CF711E5FDB80B04E0896A222F228EAF6A11351425606055411481607E4CC0F | J15: Digital PDF | K15: 6 | L15: Medium | M15: Yes | N15: No | O15: No | P15: Yes | R15: In Review | S15: Codex (batch reference draft) | U15: 批量参考草稿；需由业务人员逐条复核后改为 Approved。
A16: CASE-0011 | B16: TRENDnet | C16: TEG-082WS (v2.5R) | D16: Managed Switch | E16: l2_plus | F16: UN | G16: English | H16: C:\Users\admin\Desktop\test\EN_datasheet_TEG-082WS_(v2.5R).pdf | I16: 44AD08AB1453EA3316BF59EB3D96E905D2DB7144E4FDB1A3ECCBCE5FAC615BD2 | J16: Digital PDF | K16: 4 | L16: Medium | M16: Yes | N16: No | O16: No | P16: Yes | R16: In Review | S16: Codex (batch reference draft) | U16: 批量参考草稿；需由业务人员逐条复核后改为 Approved。
A17: CASE-0012 | B17: H3C | C17: S6550X-32H-HI | D17: Managed Switch | E17: l3 | F17: UN | G17: English | H17: C:\Users\admin\Desktop\test\H3C S6550X-HI Switch Series Hardware Information and Specifications-6W101-book.pdf | I17: B282D6C404806CBEA4BD19120362216D2CBB86415532D71323794296022CFC63 | J17: Digital PDF | K17: 24 | L17: High | M17: Yes | N17: No | O17: Yes | P17: Yes | Q17: Other H3C S6550X-HI series models | R17: In Review | S17: Codex (batch reference draft) | U17: 批量参考草稿；需由业务人员逐条复核后改为 Approved。 该 PDF 包含多个相近型号，标准答案仅针对 Target_Model。
A18: CASE-0013 | B18: Aruba | C18: J9283D | D18: Accessories | E18: dac_cable | F18: UN | G18: English | H18: C:\Users\admin\Desktop\test\HPE Aruba Networking 10G SFP+ to SFP+ 3m Direct Attach Copper Cable data sheet-PSN1010420529PLEN.pdf | I18: D23CB1BD2C71CC2602071F74BDDDB7D891BB6FDE9A511D8E2945A699795BDDFA | J18: Digital PDF | K18: 3 | L18: Low | M18: Yes | N18: No | O18: No | P18: Yes | R18: In Review | S18: Codex (batch reference draft) | U18: 批量参考草稿；需由业务人员逐条复核后改为 Approved。
A19: CASE-0014 | B19: Aruba | C19: 2530-24 Switch (J9782A) | D19: Managed Switch | E19: l2 | F19: UN | G19: English | H19: C:\Users\admin\Desktop\test\HPE Aruba Networking 2530 Switch Series-c04111414.pdf | I19: 870AF4177F441812C9962CBB92D6456DCB9FB7A9533AD31A24255A0CBF3F9591 | J19: Digital PDF | K19: 39 | L19: High | M19: Yes | N19: No | O19: Yes | P19: Yes | Q19: Other Aruba 2530 Series models | R19: In Review | S19: Codex (batch reference draft) | U19: 批量参考草稿；需由业务人员逐条复核后改为 Approved。 该 PDF 包含多个相近型号，标准答案仅针对 Target_Model。
A20: CASE-0015 | B20: Huawei | C20: eKitEngine S310-24T4X | D20: Managed Switch | E20: l3 | F20: UN | G20: English | H20: C:\Users\admin\Desktop\test\Huawei ekitEngine S310 Series Switches Datasheet.pdf | I20: C5E2FECC15CBC04EB965CD03A3DB20F9774CF583A6DC5B82013C482F15647EBC | J20: Digital PDF | K20: 10 | L20: High | M20: Yes | N20: No | O20: Yes | P20: Yes | Q20: Other Huawei eKitEngine S310 Series models | R20: In Review | S20: Codex (batch reference draft) | U20: 批量参考草稿；需由业务人员逐条复核后改为 Approved。 该 PDF 包含多个相近型号，标准答案仅针对 Target_Model。
A21: CASE-0016 | B21: Meraki | C21: MS250-24-HW | D21: Managed Switch | E21: l3 | F21: UN | G21: English | H21: C:\Users\admin\Desktop\test\meraki_datasheet_ms250.pdf | I21: F3D47A199A8F9DDC34631AF9DB838701DD225572F2D6B29A58ED7DD711B00457 | J21: Digital PDF | K21: 6 | L21: Medium | M21: Yes | N21: No | O21: Yes | P21: Yes | Q21: MS250-24P-HW; MS250-48-HW; MS250-48FP-HW | R21: In Review | S21: Codex (batch reference draft) | U21: 批量参考草稿；需由业务人员逐条复核后改为 Approved。 该 PDF 包含多个相近型号，标准答案仅针对 Target_Model。
A22: CASE-0017 | B22: Cisco | C22: C1300-24T-4X | D22: Managed Switch | E22: l3 | F22: UN | G22: English | H22: C:\Users\admin\Desktop\test\nb-06-cat1300-ser-data-sheet-cte-en.pdf | I22: B2868379C09805F327FDC0ECCD8FD17153ADB965C56EE9486846DDF44CA3F25C | J22: Digital PDF | K22: 41 | L22: High | M22: Yes | N22: No | O22: Yes | P22: Yes | Q22: Other Cisco Catalyst 1300/1300X Series models | R22: In Review | S22: Codex (batch reference draft) | U22: 批量参考草稿；需由业务人员逐条复核后改为 Approved。 该 PDF 包含多个相近型号，标准答案仅针对 Target_Model。
A23: CASE-0018 | B23: Zyxel | C23: PoE12-90W | D23: Accessories | E23: poe_injector | F23: UN | G23: English | H23: C:\Users\admin\Desktop\test\poe12-90w_ds.pdf | I23: 03492304F2EBB4B196ED2F7A8A275D8107F85CF6ED9BE5E24812DDA6B8ECA7DB | J23: Digital PDF | K23: 3 | L23: Low | M23: Yes | N23: No | O23: Yes | P23: Yes | Q23: PoE12-30W; PoE12-60W | R23: In Review | S23: Codex (batch reference draft) | U23: 批量参考草稿；需由业务人员逐条复核后改为 Approved。 该 PDF 包含多个相近型号，标准答案仅针对 Target_Model。
A24: CASE-0019 | B24: Reyee | C24: RG-EG105GW(T) | D24: Gateway | E24: wireless_router | F24: UN | G24: English | H24: C:\Users\admin\Desktop\test\RG-EG105GW(T)_Datasheet_Official_2026-03-02.pdf | I24: 76F3EDD132FD2A5F2FE7C7C30D009205EED6870970C60EBB50EDB8D36E3BB9B4 | J24: Digital PDF | K24: 20 | L24: High | M24: Yes | N24: No | O24: No | P24: Yes | R24: In Review | S24: Codex (batch reference draft) | U24: 批量参考草稿；需由业务人员逐条复核后改为 Approved。
A25: CASE-0020 | B25: Reyee | C25: RG-ES218GC-P | D25: Managed Switch | E25: l2 | F25: UN | G25: English | H25: C:\Users\admin\Desktop\test\RG-ES218GC-P_Datasheet_Official_2026-05-13.pdf | I25: DA6DFF2551EA53E9ECD3661AAC9F3EA5D7F1DBF63722798442CD898E013AD5DB | J25: Digital PDF | K25: 13 | L25: High | M25: Yes | N25: No | O25: No | P25: Yes | R25: In Review | S25: Codex (batch reference draft) | U25: 批量参考草稿；需由业务人员逐条复核后改为 Approved。
A26: CASE-0021 | B26: RUCKUS | C26: T670 | D26: Access Point | E26: outdoor | F26: US | G26: English | H26: C:\Users\admin\Desktop\test\RUCKUS T670 Data sheet.pdf | I26: 3B3698B4C50770BEE50EF9120E2603C7A13ED42BFADBD5036E5E64C72AD32B48 | J26: Digital PDF | K26: 6 | L26: Medium | M26: Yes | N26: No | O26: No | P26: Yes | R26: In Review | S26: Codex (batch reference draft) | U26: 批量参考草稿；需由业务人员逐条复核后改为 Approved。
A27: CASE-0022 | B27: Tenda | C27: S108 | D27: Unmanaged / Easy Smart Switch | E27: unmanaged | F27: UN | G27: English | H27: C:\Users\admin\Desktop\test\S108 V8.0 Datasheet.pdf | I27: 5C7F43C725D8D8481CB15AE447112707BB015FFBE3175F744BCEE97CB89EC1CA | J27: Digital PDF | K27: 2 | L27: Low | M27: Yes | N27: No | O27: Yes | P27: Yes | Q27: S105 | R27: In Review | S27: Codex (batch reference draft) | U27: 批量参考草稿；需由业务人员逐条复核后改为 Approved。 该 PDF 包含多个相近型号，标准答案仅针对 Target_Model。
A28: CASE-0023 | B28: Ubiquiti | C28: U7-Pro-Wall | D28: Access Point | E28: wall | F28: US | G28: English | H28: C:\Users\admin\Desktop\test\U7-Pro-Wall.pdf | I28: 5EF233EBEF38EB2F23BECCEFEBA45CE5BCCA779A86BF147B41EFDBD5691501AE | J28: Image-based PDF | K28: 4 | L28: Medium | M28: Yes | N28: No | O28: No | P28: Yes | R28: In Review | S28: Codex (batch reference draft) | U28: 批量参考草稿；需由业务人员逐条复核后改为 Approved。 该 PDF 为图像/特殊编码页面，已按渲染页面人工核对。
A29: CASE-0024 | B29: Ubiquiti | C29: UCG-Ultra | D29: Gateway | E29: integrated_gateway | F29: UN | G29: English | H29: C:\Users\admin\Desktop\test\UCG-Ultra.pdf | I29: B3E3B359ACEB9EBBBF40CE9C0C89EA32EABABC29E1EE47AA1FD53A25F27B2F77 | J29: Image-based PDF | K29: 4 | L29: Medium | M29: Yes | N29: No | O29: No | P29: Yes | R29: In Review | S29: Codex (batch reference draft) | U29: 批量参考草稿；需由业务人员逐条复核后改为 Approved。 该 PDF 为图像/特殊编码页面，已按渲染页面人工核对。

Sheet 标准答案
A1: 逐字段标准答案（Ground Truth）
A2: 一条规格一行；Normalized Value 使用数据库单位。所有写入数据库的字段必须有页码和证据。
A5: GT_ID | B5: Case_ID | C5: Spec_Code | D5: Value_Status | E5: Expected_Normalized_Value | F5: Value_Type | G5: Unit | H5: Expected_Raw_Value | I5: Page | J5: Evidence_Excerpt | K5: Scope | L5: Evidence_Grade | M5: Required_Field | N5: Annotator | O5: Reviewer | P5: Review_Status | Q5: Notes
A6: GT-000001 | B6: CASE-0001 | C6: supported_bands | D6: Published | E6: 2.4 GHz; 5 GHz | F6: text | H6: 2.4 GHz and 5 GHz; 6 GHz: No | I6: 7 | J6: 6 GHz Wi-Fi: No; operating bands are listed for 2.4 GHz and 5 GHz. | K6: Global | L6: A | M6: Yes | N6: Codex (reference draft) | P6: Approved | Q6: 依据上传 PDF 人工核验；请由业务人员复核后批准。
A7: GT-000002 | B7: CASE-0001 | C7: total_spatial_streams | D7: Published | E7: 4 | F7: integer | H7: 4 spatial streams | I7: 7 | J7: Radio design: Dual-radio; 4 spatial streams. | K7: Global | L7: A | M7: Yes | N7: Codex (reference draft) | P7: Approved | Q7: 依据上传 PDF 人工核验；请由业务人员复核后批准。
A8: GT-000003 | B8: CASE-0001 | C8: rate_2g_mbps | D8: Published | E8: 688 | F8: integer | G8: Mbps | H8: 688 Mbps | I8: 8 | J8: 2.4 GHz wireless data rate: 688 Mbps. | K8: 2.4 GHz | L8: A | M8: Yes | N8: Codex (reference draft) | P8: Approved | Q8: 依据上传 PDF 人工核验；请由业务人员复核后批准。
A9: GT-000004 | B9: CASE-0001 | C9: rate_5g_mbps | D9: Published | E9: 2882 | F9: integer | G9: Mbps | H9: 2882 Mbps | I9: 7 | J9: 5 GHz wireless data rate: 2882 Mbps. | K9: 5 GHz | L9: A | M9: Yes | N9: Codex (reference draft) | P9: Approved | Q9: 依据上传 PDF 人工核验；请由业务人员复核后批准。
A10: GT-000005 | B10: CASE-0001 | C10: rate_6g_mbps | D10: Not Applicable | F10: integer | G10: Mbps | H10: No | I10: 7 | J10: 6 GHz wireless data rate: No. | K10: 6 GHz | L10: A | M10: Yes | N10: Codex (reference draft) | P10: Approved | Q10: 依据上传 PDF 人工核验；请由业务人员复核后批准。
A11: GT-000006 | B11: CASE-0001 | C11: max_channel_width_mhz | D11: Published | E11: 160 | F11: integer | G11: MHz | H11: Auto/20/40/80/160 MHz | I11: 7 | J11: 5 GHz channel width: Auto/20/40/80/160 MHz. | K11: 5 GHz / maximum | L11: A | M11: Yes | N11: Codex (reference draft) | P11: Approved | Q11: 依据上传 PDF 人工核验；请由业务人员复核后批准。
A12: GT-000007 | B12: CASE-0001 | C12: ethernet_interfaces | D12: Published | E12: 1 × 10/100/1000/2500BASE-T | F12: text | H12: Number of 10/100/1000/2500BASE-T ports: 1 | I12: 10 | J12: Number of 10/100/1000/2500BASE-T ports: 1. | K12: Global | L12: A | M12: Yes | N12: Codex (reference draft) | P12: Approved | Q12: 依据上传 PDF 人工核验；请由业务人员复核后批准。
A13: GT-000008 | B13: CASE-0001 | C13: poe_input | D13: Published | E13: IEEE 802.3af (PoE); IEEE 802.3at (PoE+) | F13: text | H13: IEEE 802.3af (PoE); IEEE 802.3at (PoE+) | I13: 10 | J13: PoE In standard: IEEE 802.3af (PoE) and IEEE 802.3at (PoE+). | K13: Global | L13: A | M13: Yes | N13: Codex (reference draft) | P13: Approved | Q13: 依据上传 PDF 人工核验；请由业务人员复核后批准。
A14: GT-000009 | B14: CASE-0001 | C14: max_clients | D14: Published | E14: 511 | F14: integer | H14: 511 (2.4 GHz and 5 GHz enabled) | I14: 12 | J14: Maximum associated wireless clients: 511 when 2.4 GHz and 5 GHz are enabled. | K14: 2.4 + 5 GHz enabled | L14: A | M14: Yes | N14: Codex (reference draft) | P14: Approved | Q14: 依据上传 PDF 人工核验；请由业务人员复核后批准。
A15: GT-000010 | B15: CASE-0001 | C15: mimo_2g | D15: Published | E15: 2 × 2 MU-MIMO | F15: text | H15: 2.4 GHz: 2 x 2, MU-MIMO | I15: 7 | J15: Radio design: 2.4 GHz: 2 x 2, MU-MIMO. | K15: 2.4 GHz | L15: A | M15: No | N15: Codex (reference draft) | P15: Approved | Q15: 依据上传 PDF 人工核验；请由业务人员复核后批准。
A16: GT-000011 | B16: CASE-0001 | C16: mimo_5g | D16: Published | E16: 2 × 2 MU-MIMO | F16: text | H16: 5 GHz: 2 x 2, MU-MIMO | I16: 7 | J16: Radio design: 5 GHz: 2 x 2, MU-MIMO. | K16: 5 GHz | L16: A | M16: No | N16: Codex (reference draft) | P16: Approved | Q16: 依据上传 PDF 人工核验；请由业务人员复核后批准。
A17: GT-000012 | B17: CASE-0001 | C17: mimo_6g | D17: Not Applicable | F17: text | H17: 6 GHz Wi-Fi: No | I17: 7 | J17: 6 GHz Wi-Fi: No; the product is dual-radio. | K17: 6 GHz | L17: A | M17: No | N17: Codex (reference draft) | P17: Approved | Q17: 依据上传 PDF 人工核验；请由业务人员复核后批准。
A18: GT-000013 | B18: CASE-0001 | C18: antenna_type | D18: Published | E18: 2.4 GHz: 2 built-in omnidirectional antennas; 5 GHz: 3 built-in omnidirectional antennas | F18: text | H18: 2.4 GHz: 2 built-in omnidirectional antennas; 5 GHz: 3 built-in omnidirectional antennas | I18: 9 | J18: Antenna counts and type are stated separately for 2.4 GHz and 5 GHz. | K18: Per band | L18: A | M18: No | N18: Codex (reference draft) | P18: Approved | Q18: 依据上传 PDF 人工核验；请由业务人员复核后批准。
A19: GT-000014 | B19: CASE-0001 | C19: antenna_gain_dbi | D19: Published | E19: 2.4 GHz: 3.23 dBi; 5 GHz: 4.44 dBi | F19: text | G19: dBi | H19: Antenna gain (2.4 GHz): 3.23 dBi; Antenna gain (5 GHz): 4.44 dBi | I19: 9 | J19: Both 2.4 GHz and 5 GHz antenna gains are explicitly listed. | K19: Per band | L19: A | M19: No | N19: Codex (reference draft) | P19: Approved | Q19: 依据上传 PDF 人工核验；请由业务人员复核后批准。
A20: GT-000015 | B20: CASE-0001 | C20: centralized_management | D20: Published | E20: Ruijie Reyee App; eWeb; Ruijie Cloud | F20: text | H20: Ruijie Reyee App management; eWeb management; Ruijie Cloud management | I20: 14 | J20: Ruijie Reyee App, eWeb, and Ruijie Cloud management are all supported. | K20: Global | L20: A | M20: No | N20: Codex (reference draft) | P20: Approved | Q20: 依据上传 PDF 人工核验；请由业务人员复核后批准。
A21: GT-000016 | B21: CASE-0001 | C21: mesh_support | D21: Published | E21: true | F21: boolean | H21: Mesh management: Yes; AP Mesh: Yes | I21: 14 | J21: Mesh management: Yes; AP Mesh: Yes. | K21: Global | L21: A | M21: No | N21: Codex (reference draft) | P21: Approved | Q21: 依据上传 PDF 人工核验；请由业务人员复核后批准。
A22: GT-000017 | B22: CASE-0001 | C22: fast_roaming | D22: Published | E22: 802.11k/v; 802.11r; Layer 2 roaming; Layer 3 roaming; AI roaming | F22: text | H22: 802.11k/v roaming; Fast transition (802.11r); Layer 2/3 roaming; AI roaming | I22: 13 | J22: The roaming table marks 802.11k/v, 802.11r, Layer 2, Layer 3, and AI roaming as Yes. | K22: Global | L22: A | M22: No | N22: Codex (reference draft) | P22: Approved | Q22: 依据上传 PDF 人工核验；请由业务人员复核后批准。
A23: GT-000018 | B23: CASE-0001 | C23: max_power_consumption_w | D23: Published | E23: 14 | F23: decimal | G23: W | H23: 14 W | I23: 10 | J23: Maximum power consumption: 14 W. | K23: Global | L23: A | M23: No | N23: Codex (reference draft) | P23: Approved | Q23: 依据上传 PDF 人工核验；请由业务人员复核后批准。
A24: GT-000019 | B24: CASE-0001 | C24: dimensions_mm | D24: Published | E24: Ø195 × 41 mm (excluding mounting bracket) | F24: text | G24: mm | H24: Ø195 mm x 41 mm (excluding the mounting bracket) | I24: 9 | J24: Product dimensions (diameter x height): Ø195 mm x 41 mm, excluding bracket. | K24: Global | L24: A | M24: No | N24: Codex (reference draft) | P24: Approved | Q24: 依据上传 PDF 人工核验；请由业务人员复核后批准。
A25: GT-000020 | B25: CASE-0001 | C25: operating_temperature_c | D25: Published | E25: 0 °C to 40 °C | F25: text | G25: °C | H25: 0°C to 40°C (32°F to 104°F) | I25: 10 | J25: Operating temperature: 0°C to 40°C (32°F to 104°F). | K25: Global | L25: A | M25: No | N25: Codex (reference draft) | P25: Approved | Q25: 依据上传 PDF 人工核验；请由业务人员复核后批准。
A26: GT-000021 | B26: CASE-0002 | C26: wan_interfaces | D26: Published | E26: 1 × fixed GbE WAN + 1 × configurable GbE WAN/LAN | F26: text | H26: Fixed WAN Port: 1; WAN/LAN Switchable Port: 1 | I26: 1 | J26: One fixed 10/100/1000Base-TX WAN port and one 10/100/1000Base-TX WAN 2 / LAN port 6. | K26: Global | L26: A | M26: Yes | N26: Codex (batch reference draft) | P26: Approved | Q26: PDF 证据已定位；请人工复核标准化值和型号列。
A27: GT-000022 | B27: CASE-0002 | C27: lan_interfaces | D27: Published | E27: 5 × fixed GbE LAN + 1 × configurable GbE WAN/LAN | F27: text | H27: 5 fixed LAN ports; WAN/LAN switchable port | I27: 1 | J27: Five fixed 10/100/1000Base-TX LAN ports plus one WAN/LAN switchable port. | K27: Global | L27: A | M27: Yes | N27: Codex (batch reference draft) | P27: Approved | Q27: PDF 证据已定位；请人工复核标准化值和型号列。
A28: GT-000023 | B28: CASE-0002 | C28: routing_throughput_mbps | D28: Unknown | F28: decimal | G28: Mbps | H28: Not explicitly published | K28: Global | M28: Yes | N28: Codex (batch reference draft) | P28: Approved | Q28: 未自动定位到明确 PDF 证据；该行必须人工复核，必要时改为 Not Published/Not Applicable。
A29: GT-000024 | B29: CASE-0002 | C29: nat_throughput_mbps | D29: Unknown | F29: decimal | G29: Mbps | H29: Not explicitly published | K29: Global | M29: Yes | N29: Codex (batch reference draft) | P29: Approved | Q29: 未自动定位到明确 PDF 证据；该行必须人工复核，必要时改为 Not Published/Not Applicable。
A30: GT-000025 | B30: CASE-0002 | C30: vpn_throughput_mbps | D30: Unknown | F30: decimal | G30: Mbps | H30: Not explicitly published | K30: Global | M30: Yes | N30: Codex (batch reference draft) | P30: Approved | Q30: 未自动定位到明确 PDF 证据；该行必须人工复核，必要时改为 Not Published/Not Applicable。
A31: GT-000026 | B31: CASE-0002 | C31: concurrent_sessions | D31: Published | E31: 60000 | F31: integer | H31: 60k Sessions | I31: 1 | J31: The feature summary states 60k Sessions. | K31: Global | L31: A | M31: Yes | N31: Codex (batch reference draft) | P31: Approved | Q31: PDF 证据已定位；请人工复核标准化值和型号列。
A32: GT-000027 | B32: CASE-0002 | C32: vpn_protocols | D32: Published | E32: PPTP; L2TP; IPsec; L2TP over IPsec; SSL; GRE; IKEv2; OpenVPN; WireGuard | F32: text | H32: PPTP, L2TP, IPsec, L2TP over IPsec, SSL, GRE, IKEv2, OpenVPN, Wireguard | I32: 2 | J32: VPN protocols include PPTP, L2TP, IPsec, SSL, GRE, IKEv2, OpenVPN, and WireGuard. | K32: Global | L32: A | M32: Yes | N32: Codex (batch reference draft) | P32: Approved | Q32: PDF 证据已定位；请人工复核标准化值和型号列。
A33: GT-000028 | B33: CASE-0002 | C33: vpn_tunnels | D33: Published | E33: 50 | F33: integer | H33: 50 VPN | I33: 1 | J33: The feature summary states 50 VPN. | K33: Global | L33: A | M33: No | N33: Codex (batch reference draft) | P33: Approved | Q33: PDF 证据已定位；请人工复核标准化值和型号列。
A34: GT-000029 | B34: CASE-0002 | C34: wan_load_balancing | D34: Published | E34: true | F34: boolean | H34: Dual-WAN load balancing and failover | I34: 1 | J34: The router provides dual-WAN load balancing and failover. | K34: Global | L34: A | M34: No | N34: Codex (batch reference draft) | P34: Approved | Q34: PDF 证据已定位；请人工复核标准化值和型号列。
A35: GT-000030 | B35: CASE-0002 | C35: sd_wan | D35: Unknown | F35: text | K35: Global | M35: No | N35: Codex (batch reference draft) | P35: Approved | Q35: 未自动定位到明确 PDF 证据；该行必须人工复核，必要时改为 Not Published/Not Applicable。
A36: GT-000031 | B36: CASE-0002 | C36: firewall_features | D36: Published | E36: Firewall; content filtering; bandwidth management; route policy | F36: text | H36: Firewall, content filtering, bandwidth management | I36: 1 | J36: The product overview lists firewall, content filtering, bandwidth management, and route policy. | K36: Global | L36: A | M36: No | N36: Codex (batch reference draft) | P36: Approved | Q36: PDF 证据已定位；请人工复核标准化值和型号列。
A37: GT-000032 | B37: CASE-0002 | C37: controller_management | D37: Unknown | F37: text | I37: 1 | J37: Vigor2927 Series is a dual-Ethernet WAN firewall router, providing load-balancing and failover for your business continuity. Featuring VPN, QoS, route policy, firewall, content filtering, bandwidth management, captive hotspot portal, and a lot more, this is the ultimate router that does it all for SMB. The series includes built-in 802.11ax Wi-Fi and VoIP gateway models. Bandwidth Management | K37: Global | L37: A | M37: No | N37: Codex (batch reference draft) | P37: Approved | Q37: PDF 证据已定位；请人工复核标准化值和型号列。
A38: GT-000033 | B38: CASE-0002 | C38: max_power_consumption_w | D38: Unknown | F38: decimal | G38: W | K38: Global | M38: No | N38: Codex (batch reference draft) | P38: Approved | Q38: 未自动定位到明确 PDF 证据；该行必须人工复核，必要时改为 Not Published/Not Applicable。
A39: GT-000034 | B39: CASE-0002 | C39: dimensions_mm | D39: Unknown | F39: text | G39: mm | K39: Global | M39: No | N39: Codex (batch reference draft) | P39: Approved | Q39: 未自动定位到明确 PDF 证据；该行必须人工复核，必要时改为 Not Published/Not Applicable。
A40: GT-000035 | B40: CASE-0002 | C40: operating_temperature_c | D40: Unknown | F40: text | G40: °C | K40: Global | M40: No | N40: Codex (batch reference draft) | P40: Approved | Q40: 未自动定位到明确 PDF 证据；该行必须人工复核，必要时改为 Not Published/Not Applicable。
A41: GT-000036 | B41: CASE-0003 | C41: wan_interfaces | D41: Published | E41: Up to 4 configurable WAN ports | F41: text | H41: Up to 4 WANs | I41: 1 | J41: Users can set four ports as WAN for load balancing/failover. | K41: Global | L41: A | M41: Yes | N41: Codex (batch reference draft) | P41: Approved | Q41: PDF 证据已定位；请人工复核标准化值和型号列。
A42: GT-000037 | B42: CASE-0003 | C42: lan_interfaces | D42: Published | E42: 1 × 2.5GbE RJ45 + 2 × 1GbE RJ45 + 1 × GbE/SFP combo, configurable | F42: text | H42: Configurable WAN/LAN ports | I42: 1 | J42: The port selection includes one 2.5GbE port, two 1GbE ports, and one GbE/SFP combo port. | K42: Global | L42: A | M42: Yes | N42: Codex (batch reference draft) | P42: Approved | Q42: PDF 证据已定位；请人工复核标准化值和型号列。
...

Sheet 型号评测
A1: 型号校验评测
A2: 黄色为运行结果输入；灰色为从案例清单读取或自动判定。
A5: Run_ID | B5: Case_ID | C5: Expected_Match | D5: Target_Model | E5: Predicted_Match | F5: Predicted_Model | G5: Evidence_Page | H5: Evidence_Excerpt | I5: Verdict | J5: Algorithm_Version | K5: Notes
C6: =IFERROR(INDEX(案例清单!$P$6:$P$55,MATCH(B6,案例清单!$A$6:$A$55,0)),"") | D6: =IFERROR(INDEX(案例清单!$C$6:$C$55,MATCH(B6,案例清单!$A$6:$A$55,0)),"") | I6: =IF(OR(A6="",B6="",E6=""),"",IF(AND(C6="Yes",E6="Yes",UPPER(TRIM(D6))=UPPER(TRIM(F6))),"Correct",IF(AND(C6="No",E6="No"),"Correct",IF(AND(C6="No",E6="Yes"),"False Accept",IF(AND(C6="Yes",E6="No"),"False Reject","Wrong Model")))))
C7: =IFERROR(INDEX(案例清单!$P$6:$P$55,MATCH(B7,案例清单!$A$6:$A$55,0)),"") | D7: =IFERROR(INDEX(案例清单!$C$6:$C$55,MATCH(B7,案例清单!$A$6:$A$55,0)),"") | I7: =IF(OR(A7="",B7="",E7=""),"",IF(AND(C7="Yes",E7="Yes",UPPER(TRIM(D7))=UPPER(TRIM(F7))),"Correct",IF(AND(C7="No",E7="No"),"Correct",IF(AND(C7="No",E7="Yes"),"False Accept",IF(AND(C7="Yes",E7="No"),"False Reject","Wrong Model")))))
C8: =IFERROR(INDEX(案例清单!$P$6:$P$55,MATCH(B8,案例清单!$A$6:$A$55,0)),"") | D8: =IFERROR(INDEX(案例清单!$C$6:$C$55,MATCH(B8,案例清单!$A$6:$A$55,0)),"") | I8: =IF(OR(A8="",B8="",E8=""),"",IF(AND(C8="Yes",E8="Yes",UPPER(TRIM(D8))=UPPER(TRIM(F8))),"Correct",IF(AND(C8="No",E8="No"),"Correct",IF(AND(C8="No",E8="Yes"),"False Accept",IF(AND(C8="Yes",E8="No"),"False Reject","Wrong Model")))))
C9: =IFERROR(INDEX(案例清单!$P$6:$P$55,MATCH(B9,案例清单!$A$6:$A$55,0)),"") | D9: =IFERROR(INDEX(案例清单!$C$6:$C$55,MATCH(B9,案例清单!$A$6:$A$55,0)),"") | I9: =IF(OR(A9="",B9="",E9=""),"",IF(AND(C9="Yes",E9="Yes",UPPER(TRIM(D9))=UPPER(TRIM(F9))),"Correct",IF(AND(C9="No",E9="No"),"Correct",IF(AND(C9="No",E9="Yes"),"False Accept",IF(AND(C9="Yes",E9="No"),"False Reject","Wrong Model")))))
C10: =IFERROR(INDEX(案例清单!$P$6:$P$55,MATCH(B10,案例清单!$A$6:$A$55,0)),"") | D10: =IFERROR(INDEX(案例清单!$C$6:$C$55,MATCH(B10,案例清单!$A$6:$A$55,0)),"") | I10: =IF(OR(A10="",B10="",E10=""),"",IF(AND(C10="Yes",E10="Yes",UPPER(TRIM(D10))=UPPER(TRIM(F10))),"Correct",IF(AND(C10="No",E10="No"),"Correct",IF(AND(C10="No",E10="Yes"),"False Accept",IF(AND(C10="Yes",E10="No"),"False Reject","Wrong Model")))))
C11: =IFERROR(INDEX(案例清单!$P$6:$P$55,MATCH(B11,案例清单!$A$6:$A$55,0)),"") | D11: =IFERROR(INDEX(案例清单!$C$6:$C$55,MATCH(B11,案例清单!$A$6:$A$55,0)),"") | I11: =IF(OR(A11="",B11="",E11=""),"",IF(AND(C11="Yes",E11="Yes",UPPER(TRIM(D11))=UPPER(TRIM(F11))),"Correct",IF(AND(C11="No",E11="No"),"Correct",IF(AND(C11="No",E11="Yes"),"False Accept",IF(AND(C11="Yes",E11="No"),"False Reject","Wrong Model")))))
C12: =IFERROR(INDEX(案例清单!$P$6:$P$55,MATCH(B12,案例清单!$A$6:$A$55,0)),"") | D12: =IFERROR(INDEX(案例清单!$C$6:$C$55,MATCH(B12,案例清单!$A$6:$A$55,0)),"") | I12: =IF(OR(A12="",B12="",E12=""),"",IF(AND(C12="Yes",E12="Yes",UPPER(TRIM(D12))=UPPER(TRIM(F12))),"Correct",IF(AND(C12="No",E12="No"),"Correct",IF(AND(C12="No",E12="Yes"),"False Accept",IF(AND(C12="Yes",E12="No"),"False Reject","Wrong Model")))))
C13: =IFERROR(INDEX(案例清单!$P$6:$P$55,MATCH(B13,案例清单!$A$6:$A$55,0)),"") | D13: =IFERROR(INDEX(案例清单!$C$6:$C$55,MATCH(B13,案例清单!$A$6:$A$55,0)),"") | I13: =IF(OR(A13="",B13="",E13=""),"",IF(AND(C13="Yes",E13="Yes",UPPER(TRIM(D13))=UPPER(TRIM(F13))),"Correct",IF(AND(C13="No",E13="No"),"Correct",IF(AND(C13="No",E13="Yes"),"False Accept",IF(AND(C13="Yes",E13="No"),"False Reject","Wrong Model")))))
C14: =IFERROR(INDEX(案例清单!$P$6:$P$55,MATCH(B14,案例清单!$A$6:$A$55,0)),"") | D14: =IFERROR(INDEX(案例清单!$C$6:$C$55,MATCH(B14,案例清单!$A$6:$A$55,0)),"") | I14: =IF(OR(A14="",B14="",E14=""),"",IF(AND(C14="Yes",E14="Yes",UPPER(TRIM(D14))=UPPER(TRIM(F14))),"Correct",IF(AND(C14="No",E14="No"),"Correct",IF(AND(C14="No",E14="Yes"),"False Accept",IF(AND(C14="Yes",E14="No"),"False Reject","Wrong Model")))))
C15: =IFERROR(INDEX(案例清单!$P$6:$P$55,MATCH(B15,案例清单!$A$6:$A$55,0)),"") | D15: =IFERROR(INDEX(案例清单!$C$6:$C$55,MATCH(B15,案例清单!$A$6:$A$55,0)),"") | I15: =IF(OR(A15="",B15="",E15=""),"",IF(AND(C15="Yes",E15="Yes",UPPER(TRIM(D15))=UPPER(TRIM(F15))),"Correct",IF(AND(C15="No",E15="No"),"Correct",IF(AND(C15="No",E15="Yes"),"False Accept",IF(AND(C15="Yes",E15="No"),"False Reject","Wrong Model")))))
C16: =IFERROR(INDEX(案例清单!$P$6:$P$55,MATCH(B16,案例清单!$A$6:$A$55,0)),"") | D16: =IFERROR(INDEX(案例清单!$C$6:$C$55,MATCH(B16,案例清单!$A$6:$A$55,0)),"") | I16: =IF(OR(A16="",B16="",E16=""),"",IF(AND(C16="Yes",E16="Yes",UPPER(TRIM(D16))=UPPER(TRIM(F16))),"Correct",IF(AND(C16="No",E16="No"),"Correct",IF(AND(C16="No",E16="Yes"),"False Accept",IF(AND(C16="Yes",E16="No"),"False Reject","Wrong Model")))))
C17: =IFERROR(INDEX(案例清单!$P$6:$P$55,MATCH(B17,案例清单!$A$6:$A$55,0)),"") | D17: =IFERROR(INDEX(案例清单!$C$6:$C$55,MATCH(B17,案例清单!$A$6:$A$55,0)),"") | I17: =IF(OR(A17="",B17="",E17=""),"",IF(AND(C17="Yes",E17="Yes",UPPER(TRIM(D17))=UPPER(TRIM(F17))),"Correct",IF(AND(C17="No",E17="No"),"Correct",IF(AND(C17="No",E17="Yes"),"False Accept",IF(AND(C17="Yes",E17="No"),"False Reject","Wrong Model")))))
... C55: =IFERROR(INDEX(案例清单!$P$6:$P$55,MATCH(B55,案例清单!$A$6:$A$55,0)),"") | D55: =IFERROR(INDEX(案例清单!$C$6:$C$55,MATCH(B55,案例清单!$A$6:$A$55,0)),"") | I55: =IF(OR(A55="",B55="",E55=""),"",IF(AND(C55="Yes",E55="Yes",UPPER(TRIM(D55))=UPPER(TRIM(F55))),"Correct",IF(AND(C55="No",E55="No"),"Correct",IF(AND(C55="No",E55="Yes"),"False Accept",IF(AND(C55="Yes",E55="No"),"False Reject","Wrong Model")))))

Sheet 规格评测
A1: 逐字段规格评测
A2: 每个 GT_ID 每次运行一行；额外预测留空 GT_ID。判定公式区分 TP、FP、FN 和 VALUE_ERROR。
A5: Run_ID | B5: Case_ID | C5: GT_ID | D5: Spec_Code | E5: Expected_Normalized | F5: Expected_Status | G5: Predicted_Normalized | H5: Predicted_Status | I5: System_Confidence | J5: Evidence_Page | K5: Evidence_Excerpt | L5: Evidence_Correct | M5: Value_Verdict | N5: Error_Type | O5: Notes
D6: =IF(C6="","",IFERROR(INDEX(标准答案!$C$6:$C$105,MATCH(C6,标准答案!$A$6:$A$105,0)),"")) | E6: =IF(C6="","",IFERROR(INDEX(标准答案!$E$6:$E$105,MATCH(C6,标准答案!$A$6:$A$105,0)),"")) | F6: =IF(C6="","",IFERROR(INDEX(标准答案!$D$6:$D$105,MATCH(C6,标准答案!$A$6:$A$105,0)),"")) | M6: =IF(OR(A6="",B6=""),"",IF(AND(C6="",H6<>""),"FP",IF(AND(C6<>"",H6=""),"FN",IF(F6<>H6,"VALUE_ERROR",IF(F6<>"Published","TP",IF(UPPER(TRIM(E6))=UPPER(TRIM(G6)),"TP","VALUE_ERROR"))))))
D7: =IF(C7="","",IFERROR(INDEX(标准答案!$C$6:$C$105,MATCH(C7,标准答案!$A$6:$A$105,0)),"")) | E7: =IF(C7="","",IFERROR(INDEX(标准答案!$E$6:$E$105,MATCH(C7,标准答案!$A$6:$A$105,0)),"")) | F7: =IF(C7="","",IFERROR(INDEX(标准答案!$D$6:$D$105,MATCH(C7,标准答案!$A$6:$A$105,0)),"")) | M7: =IF(OR(A7="",B7=""),"",IF(AND(C7="",H7<>""),"FP",IF(AND(C7<>"",H7=""),"FN",IF(F7<>H7,"VALUE_ERROR",IF(F7<>"Published","TP",IF(UPPER(TRIM(E7))=UPPER(TRIM(G7)),"TP","VALUE_ERROR"))))))
D8: =IF(C8="","",IFERROR(INDEX(标准答案!$C$6:$C$105,MATCH(C8,标准答案!$A$6:$A$105,0)),"")) | E8: =IF(C8="","",IFERROR(INDEX(标准答案!$E$6:$E$105,MATCH(C8,标准答案!$A$6:$A$105,0)),"")) | F8: =IF(C8="","",IFERROR(INDEX(标准答案!$D$6:$D$105,MATCH(C8,标准答案!$A$6:$A$105,0)),"")) | M8: =IF(OR(A8="",B8=""),"",IF(AND(C8="",H8<>""),"FP",IF(AND(C8<>"",H8=""),"FN",IF(F8<>H8,"VALUE_ERROR",IF(F8<>"Published","TP",IF(UPPER(TRIM(E8))=UPPER(TRIM(G8)),"TP","VALUE_ERROR"))))))
D9: =IF(C9="","",IFERROR(INDEX(标准答案!$C$6:$C$105,MATCH(C9,标准答案!$A$6:$A$105,0)),"")) | E9: =IF(C9="","",IFERROR(INDEX(标准答案!$E$6:$E$105,MATCH(C9,标准答案!$A$6:$A$105,0)),"")) | F9: =IF(C9="","",IFERROR(INDEX(标准答案!$D$6:$D$105,MATCH(C9,标准答案!$A$6:$A$105,0)),"")) | M9: =IF(OR(A9="",B9=""),"",IF(AND(C9="",H9<>""),"FP",IF(AND(C9<>"",H9=""),"FN",IF(F9<>H9,"VALUE_ERROR",IF(F9<>"Published","TP",IF(UPPER(TRIM(E9))=UPPER(TRIM(G9)),"TP","VALUE_ERROR"))))))
D10: =IF(C10="","",IFERROR(INDEX(标准答案!$C$6:$C$105,MATCH(C10,标准答案!$A$6:$A$105,0)),"")) | E10: =IF(C10="","",IFERROR(INDEX(标准答案!$E$6:$E$105,MATCH(C10,标准答案!$A$6:$A$105,0)),"")) | F10: =IF(C10="","",IFERROR(INDEX(标准答案!$D$6:$D$105,MATCH(C10,标准答案!$A$6:$A$105,0)),"")) | M10: =IF(OR(A10="",B10=""),"",IF(AND(C10="",H10<>""),"FP",IF(AND(C10<>"",H10=""),"FN",IF(F10<>H10,"VALUE_ERROR",IF(F10<>"Published","TP",IF(UPPER(TRIM(E10))=UPPER(TRIM(G10)),"TP","VALUE_ERROR"))))))
D11: =IF(C11="","",IFERROR(INDEX(标准答案!$C$6:$C$105,MATCH(C11,标准答案!$A$6:$A$105,0)),"")) | E11: =IF(C11="","",IFERROR(INDEX(标准答案!$E$6:$E$105,MATCH(C11,标准答案!$A$6:$A$105,0)),"")) | F11: =IF(C11="","",IFERROR(INDEX(标准答案!$D$6:$D$105,MATCH(C11,标准答案!$A$6:$A$105,0)),"")) | M11: =IF(OR(A11="",B11=""),"",IF(AND(C11="",H11<>""),"FP",IF(AND(C11<>"",H11=""),"FN",IF(F11<>H11,"VALUE_ERROR",IF(F11<>"Published","TP",IF(UPPER(TRIM(E11))=UPPER(TRIM(G11)),"TP","VALUE_ERROR"))))))
D12: =IF(C12="","",IFERROR(INDEX(标准答案!$C$6:$C$105,MATCH(C12,标准答案!$A$6:$A$105,0)),"")) | E12: =IF(C12="","",IFERROR(INDEX(标准答案!$E$6:$E$105,MATCH(C12,标准答案!$A$6:$A$105,0)),"")) | F12: =IF(C12="","",IFERROR(INDEX(标准答案!$D$6:$D$105,MATCH(C12,标准答案!$A$6:$A$105,0)),"")) | M12: =IF(OR(A12="",B12=""),"",IF(AND(C12="",H12<>""),"FP",IF(AND(C12<>"",H12=""),"FN",IF(F12<>H12,"VALUE_ERROR",IF(F12<>"Published","TP",IF(UPPER(TRIM(E12))=UPPER(TRIM(G12)),"TP","VALUE_ERROR"))))))
D13: =IF(C13="","",IFERROR(INDEX(标准答案!$C$6:$C$105,MATCH(C13,标准答案!$A$6:$A$105,0)),"")) | E13: =IF(C13="","",IFERROR(INDEX(标准答案!$E$6:$E$105,MATCH(C13,标准答案!$A$6:$A$105,0)),"")) | F13: =IF(C13="","",IFERROR(INDEX(标准答案!$D$6:$D$105,MATCH(C13,标准答案!$A$6:$A$105,0)),"")) | M13: =IF(OR(A13="",B13=""),"",IF(AND(C13="",H13<>""),"FP",IF(AND(C13<>"",H13=""),"FN",IF(F13<>H13,"VALUE_ERROR",IF(F13<>"Published","TP",IF(UPPER(TRIM(E13))=UPPER(TRIM(G13)),"TP","VALUE_ERROR"))))))
D14: =IF(C14="","",IFERROR(INDEX(标准答案!$C$6:$C$105,MATCH(C14,标准答案!$A$6:$A$105,0)),"")) | E14: =IF(C14="","",IFERROR(INDEX(标准答案!$E$6:$E$105,MATCH(C14,标准答案!$A$6:$A$105,0)),"")) | F14: =IF(C14="","",IFERROR(INDEX(标准答案!$D$6:$D$105,MATCH(C14,标准答案!$A$6:$A$105,0)),"")) | M14: =IF(OR(A14="",B14=""),"",IF(AND(C14="",H14<>""),"FP",IF(AND(C14<>"",H14=""),"FN",IF(F14<>H14,"VALUE_ERROR",IF(F14<>"Published","TP",IF(UPPER(TRIM(E14))=UPPER(TRIM(G14)),"TP","VALUE_ERROR"))))))
D15: =IF(C15="","",IFERROR(INDEX(标准答案!$C$6:$C$105,MATCH(C15,标准答案!$A$6:$A$105,0)),"")) | E15: =IF(C15="","",IFERROR(INDEX(标准答案!$E$6:$E$105,MATCH(C15,标准答案!$A$6:$A$105,0)),"")) | F15: =IF(C15="","",IFERROR(INDEX(标准答案!$D$6:$D$105,MATCH(C15,标准答案!$A$6:$A$105,0)),"")) | M15: =IF(OR(A15="",B15=""),"",IF(AND(C15="",H15<>""),"FP",IF(AND(C15<>"",H15=""),"FN",IF(F15<>H15,"VALUE_ERROR",IF(F15<>"Published","TP",IF(UPPER(TRIM(E15))=UPPER(TRIM(G15)),"TP","VALUE_ERROR"))))))
D16: =IF(C16="","",IFERROR(INDEX(标准答案!$C$6:$C$105,MATCH(C16,标准答案!$A$6:$A$105,0)),"")) | E16: =IF(C16="","",IFERROR(INDEX(标准答案!$E$6:$E$105,MATCH(C16,标准答案!$A$6:$A$105,0)),"")) | F16: =IF(C16="","",IFERROR(INDEX(标准答案!$D$6:$D$105,MATCH(C16,标准答案!$A$6:$A$105,0)),"")) | M16: =IF(OR(A16="",B16=""),"",IF(AND(C16="",H16<>""),"FP",IF(AND(C16<>"",H16=""),"FN",IF(F16<>H16,"VALUE_ERROR",IF(F16<>"Published","TP",IF(UPPER(TRIM(E16))=UPPER(TRIM(G16)),"TP","VALUE_ERROR"))))))
D17: =IF(C17="","",IFERROR(INDEX(标准答案!$C$6:$C$105,MATCH(C17,标准答案!$A$6:$A$105,0)),"")) | E17: =IF(C17="","",IFERROR(INDEX(标准答案!$E$6:$E$105,MATCH(C17,标准答案!$A$6:$A$105,0)),"")) | F17: =IF(C17="","",IFERROR(INDEX(标准答案!$D$6:$D$105,MATCH(C17,标准答案!$A$6:$A$105,0)),"")) | M17: =IF(OR(A17="",B17=""),"",IF(AND(C17="",H17<>""),"FP",IF(AND(C17<>"",H17=""),"FN",IF(F17<>H17,"VALUE_ERROR",IF(F17<>"Published","TP",IF(UPPER(TRIM(E17))=UPPER(TRIM(G17)),"TP","VALUE_ERROR"))))))
... D105: =IF(C105="","",IFERROR(INDEX(标准答案!$C$6:$C$105,MATCH(C105,标准答案!$A$6:$A$105,0)),"")) | E105: =IF(C105="","",IFERROR(INDEX(标准答案!$E$6:$E$105,MATCH(C105,标准答案!$A$6:$A$105,0)),"")) | F105: =IF(C105="","",IFERROR(INDEX(标准答案!$D$6:$D$105,MATCH(C105,标准答案!$A$6:$A$105,0)),"")) | M105: =IF(OR(A105="",B105=""),"",IF(AND(C105="",H105<>""),"FP",IF(AND(C105<>"",H105=""),"FN",IF(F105<>H105,"VALUE_ERROR",IF(F105<>"Published","TP",IF(UPPER(TRIM(E105))=UPPER(TRIM(G105)),"TP","VALUE_ERROR"))))))

Sheet 运行记录
A1: 算法运行记录
A2: 每个 Run × Case 一行；时间使用真实日期时间，Total Seconds 自动计算。
A5: Run_ID | B5: Algorithm_Version | C5: Case_ID | D5: Started_At | E5: Completed_At | F5: Total_Seconds | G5: Parse_Seconds | H5: AI_Seconds | I5: Peak_RAM_MB | J5: Input_Tokens | K5: Output_Tokens | L5: Predicted_Spec_Count | M5: Accepted_Spec_Count | N5: Run_Status | O5: Error_Message
F6: =IF(OR(D6="",E6=""),"",ROUND((E6-D6)*86400,1))
F7: =IF(OR(D7="",E7=""),"",ROUND((E7-D7)*86400,1))
F8: =IF(OR(D8="",E8=""),"",ROUND((E8-D8)*86400,1))
F9: =IF(OR(D9="",E9=""),"",ROUND((E9-D9)*86400,1))
F10: =IF(OR(D10="",E10=""),"",ROUND((E10-D10)*86400,1))
F11: =IF(OR(D11="",E11=""),"",ROUND((E11-D11)*86400,1))
F12: =IF(OR(D12="",E12=""),"",ROUND((E12-D12)*86400,1))
F13: =IF(OR(D13="",E13=""),"",ROUND((E13-D13)*86400,1))
F14: =IF(OR(D14="",E14=""),"",ROUND((E14-D14)*86400,1))
F15: =IF(OR(D15="",E15=""),"",ROUND((E15-D15)*86400,1))
F16: =IF(OR(D16="",E16=""),"",ROUND((E16-D16)*86400,1))
F17: =IF(OR(D17="",E17=""),"",ROUND((E17-D17)*86400,1))
... F55: =IF(OR(D55="",E55=""),"",ROUND((E55-D55)*86400,1))

Sheet 字段字典
A1: 当前系统规格字段字典
A2: 从正式数据库读取；用于选择 Spec_Code、数据类型、单位及适用产品形态。
A4: Category | B4: Spec_Code | C4: Display_Name | D4: Group | E4: Data_Type | F4: Unit | G4: Core | H4: Applicable_Form_Factors | I4: Template_Priority | J4: Required_In_Any_Template
A5: General | B5: ethernet_interfaces | C5: Ethernet Interfaces | D5: Interfaces | E5: text | G5: Yes | J5: No
A6: General | B6: max_power_consumption_w | C6: Maximum Power Consumption | D6: Power | E6: decimal | F6: W | G6: Yes | J6: No
A7: General | B7: fanless | C7: Fanless Design | D7: Physical | E7: boolean | G7: Yes | J7: No
A8: General | B8: ip_rating | C8: IP / Weatherproof Rating | D8: Environment | E8: text | G8: Yes | J8: No
A9: General | B9: lightning_protection_kv | C9: Lightning / Surge Protection | D9: Environment | E9: text | F9: kV | G9: Yes | J9: No
A10: General | B10: operating_temperature_c | C10: Operating Temperature | D10: Environment | E10: text | F10: °C | G10: Yes | J10: No
A11: General | B11: dimensions_mm | C11: Dimensions | D11: Physical | E11: text | F11: mm | G11: Yes | J11: No
A12: Access Point | B12: supported_bands | C12: Supported Wireless Bands | D12: Wireless | E12: text | G12: Yes | H12: ceiling, desktop, extender, outdoor, wall, wall_plate, 通用 | I12: p0 | J12: Yes
A13: Access Point | B13: total_spatial_streams | C13: Total Spatial Streams | D13: Wireless | E13: integer | G13: Yes | H13: ceiling, desktop, outdoor, wall, wall_plate, 通用 | I13: p0 | J13: Yes
A14: Access Point | B14: mimo_2g | C14: 2.4 GHz MIMO | D14: Wireless | E14: text | G14: Yes | H14: ceiling, wall_plate, 通用 | I14: p0, p1 | J14: Yes
A15: Access Point | B15: mimo_5g | C15: 5 GHz MIMO | D15: Wireless | E15: text | G15: Yes | H15: ceiling, wall_plate, 通用 | I15: p0, p1 | J15: Yes
A16: Access Point | B16: mimo_6g | C16: 6 GHz MIMO | D16: Wireless | E16: text | G16: Yes | H16: ceiling, wall_plate, 通用 | I16: p0, p1 | J16: Yes
A17: Access Point | B17: rate_2g_mbps | C17: 2.4 GHz Max Rate | D17: Performance | E17: integer | F17: Mbps | G17: Yes | H17: ceiling, desktop, extender, outdoor, wall, wall_plate, 通用 | I17: p0 | J17: Yes
A18: Access Point | B18: rate_5g_mbps | C18: 5 GHz Max Rate | D18: Performance | E18: integer | F18: Mbps | G18: Yes | H18: ceiling, desktop, extender, outdoor, wall, wall_plate, 通用 | I18: p0 | J18: Yes
A19: Access Point | B19: rate_6g_mbps | C19: 6 GHz Max Rate | D19: Performance | E19: integer | F19: Mbps | G19: Yes | H19: ceiling, desktop, extender, outdoor, wall, wall_plate, 通用 | I19: p0 | J19: Yes
A20: Access Point | B20: max_channel_width_mhz | C20: Max Channel Width | D20: Wireless | E20: integer | F20: MHz | G20: Yes | H20: ceiling, desktop, extender, outdoor, wall, wall_plate, 通用 | I20: p0, p1 | J20: Yes
A21: Access Point | B21: antenna_type | C21: Antenna Type | D21: Wireless | E21: text | G21: Yes | H21: ceiling, desktop, extender, outdoor, wall, 通用 | I21: p0, p1 | J21: Yes
A22: Access Point | B22: antenna_gain_dbi | C22: Antenna Gain | D22: Wireless | E22: text | F22: dBi | G22: Yes | H22: ceiling, outdoor, wall, 通用 | I22: p0, p1 | J22: Yes
A23: Access Point | B23: max_clients | C23: Maximum Clients | D23: Capacity | E23: integer | G23: Yes | H23: ceiling, desktop, outdoor, wall, wall_plate, 通用 | I23: p0 | J23: Yes
A24: Access Point | B24: max_ssids | C24: Maximum SSIDs | D24: Capacity | E24: integer | G24: Yes | H24: wall_plate, 通用 | I24: p1 | J24: No
A25: Access Point | B25: poe_input | C25: PoE Input | D25: Power | E25: text | G25: Yes | H25: ceiling, desktop, outdoor, wall, wall_plate, 通用 | I25: p0 | J25: Yes
A26: Access Point | B26: poe_output | C26: PoE Output | D26: Power | E26: text | G26: Yes | H26: desktop, wall_plate | I26: p0, p1 | J26: Yes
A27: Access Point | B27: centralized_management | C27: Centralized Management | D27: Management | E27: text | G27: Yes | H27: ceiling, desktop, outdoor, wall, wall_plate, 通用 | I27: p1 | J27: No
A28: Access Point | B28: mesh_support | C28: Mesh Support | D28: Management | E28: boolean | G28: Yes | H28: ceiling, extender, outdoor, 通用 | I28: p1 | J28: No
A29: Access Point | B29: fast_roaming | C29: Fast Roaming | D29: Management | E29: text | G29: Yes | H29: ceiling, outdoor, wall_plate, 通用 | I29: p1 | J29: No
A30: Access Point | B30: wireless_security | C30: Wireless Security | D30: Security | E30: text | G30: Yes | H30: extender, outdoor, wall_plate, 通用 | I30: p1 | J30: No
A31: Accessories | B31: accessory_connector_type | C31: Connector Type | D31: Interfaces | E31: text | G31: Yes | H31: antenna, media_converter, optical_module, 通用 | I31: p0 | J31: Yes
A32: Accessories | B32: accessory_interface_type | C32: Interface Type | D32: Interfaces | E32: text | G32: Yes | H32: dac_cable, media_converter, optical_module, poe_injector, 通用 | I32: p0 | J32: Yes
A33: Accessories | B33: accessory_data_rate_gbps | C33: Maximum Data Rate | D33: Performance | E33: decimal | F33: Gbps | G33: Yes | H33: dac_cable, media_converter, optical_module, poe_injector | I33: p0 | J33: Yes
A34: Accessories | B34: accessory_input_power | C34: Input Power | D34: Power | E34: text | G34: Yes | H34: chassis, media_converter, poe_injector, power_supply | I34: p0 | J34: Yes
A35: Accessories | B35: accessory_output_power | C35: Output Power | D35: Power | E35: text | G35: Yes | H35: poe_injector, power_supply | I35: p0 | J35: Yes
A36: Accessories | B36: accessory_poe_standard | C36: PoE Standard | D36: Power | E36: text | G36: Yes | H36: poe_injector | I36: p0 | J36: Yes
A37: Accessories | B37: accessory_power_w | C37: Maximum Output Power | D37: Power | E37: decimal | F37: W | G37: Yes | H37: poe_injector, power_supply | I37: p0 | J37: Yes
A38: Accessories | B38: accessory_wavelength_nm | C38: Wavelength | D38: Optical | E38: integer | F38: nm | G38: Yes | H38: optical_module | I38: p0 | J38: Yes
A39: Accessories | B39: accessory_fiber_mode | C39: Fiber Mode | D39: Optical | E39: text | G39: Yes | H39: media_converter, optical_module | I39: p0 | J39: Yes
A40: Accessories | B40: accessory_max_distance_km | C40: Maximum Transmission Distance | D40: Optical | E40: decimal | F40: km | G40: Yes | H40: media_converter, optical_module | I40: p0 | J40: Yes
A41: Accessories | B41: accessory_cable_length_m | C41: Cable Length | D41: Physical | E41: decimal | F41: m | G41: Yes | H41: dac_cable | I41: p0 | J41: Yes
...

Sheet 枚举选项
A1: 枚举与下拉选项
A2: 数据验证引用区域；可以增加选项，但不要改变现有含义。
A4: Category | B4: Product Type Code | C4: Product Type Name | D4: Document Kind | E4: Complexity | F4: Yes/No | G4: Review Status | H4: Value Status | I4: Value Type | J4: Evidence Grade | K4: Model Verdict
A5: Access Point | B5: ceiling | C5: Ceiling Mount — Access Point | D5: Digital PDF | E5: Low | F5: Yes | G5: Draft | H5: Published | I5: text | J5: A | K5: Correct
A6: Accessories | B6: wall | C6: Wall Mount — Access Point | D6: Scanned PDF | E6: Medium | F6: No | G6: Annotated | H6: Not Published | I6: integer | J6: B | K6: False Accept
A7: Gateway | B7: wall_plate | C7: Wall Plate — Access Point | D7: Mixed PDF | E7: High | G7: In Review | H7: Not Applicable | I7: decimal | J7: C | K7: False Reject
A8: Managed Switch | B8: outdoor | C8: Outdoor — Access Point | D8: HTML | G8: Approved | H8: Unknown | I8: boolean | K8: Wrong Model
A9: Routing | B9: desktop | C9: Desktop — Access Point | G9: Rejected | I9: choice
A10: Switching | B10: extender | C10: Extender — Access Point
A11: Unmanaged / Easy Smart Switch | B11: other | C11: Other AP — Access Point
A12: Wireless | B12: poe_injector | C12: PoE Injector — Accessories
A13: Wireless Bridge | B13: power_supply | C13: Power Supply — Accessories
B14: media_converter | C14: Media Converter — Accessories
B15: optical_module | C15: Optical Module — Accessories
B16: dac_cable | C16: DAC Cable — Accessories
B17: mounting | C17: Mounting Accessory — Accessories
B18: chassis | C18: Chassis — Accessories
B19: antenna | C19: Antenna — Accessories
B20: junction_box | C20: Junction Box — Accessories
B21: other | C21: Other Accessory — Accessories
B22: wired_router | C22: Wired Router — Gateway
B23: wireless_router | C23: Wireless Router — Gateway
B24: cellular_router | C24: Cellular Router — Gateway
B25: outdoor_cellular_router | C25: Outdoor Cellular Router — Gateway
... B34: unknown | C34: Unknown Management Type — Unmanaged / Easy Smart Switch
